2023-08-03 23:30:38,235 - DEBUG - This is a debug message
2023-08-03 23:30:38,239 - ERROR - This is an error message
2023-08-03 23:30:38,242 - ERROR - An error occurred while dividing by zero:
Traceback (most recent call last):
  File "/tmp/ipykernel_67526/468990844.py", line 19, in <module>
    result = 10 / 0
             ~~~^~~
ZeroDivisionError: division by zero
2023-08-03 23:31:20,363 - DEBUG - This is a debug message
2023-08-03 23:31:20,366 - ERROR - This is an error message
2023-08-04 09:42:40,789 - DEBUG - This is a debug message
2023-08-04 09:42:40,796 - ERROR - This is an error message
2023-08-04 09:42:40,800 - ERROR - An error occurred while dividing by zero:
Traceback (most recent call last):
  File "/tmp/ipykernel_82372/3924246926.py", line 6, in <module>
    result = 10 / 0
             ~~~^~~
ZeroDivisionError: division by zero
2023-08-04 09:43:24,566 - DEBUG - This is a debug message
2023-08-04 09:43:24,566 - DEBUG - This is a debug message
2023-08-04 09:43:24,570 - ERROR - This is an error message
2023-08-04 09:43:24,570 - ERROR - This is an error message
2023-08-04 09:43:24,571 - ERROR - An error occurred while dividing by zero:
Traceback (most recent call last):
  File "/tmp/ipykernel_82372/3924246926.py", line 6, in <module>
    result = 10 / 0
             ~~~^~~
ZeroDivisionError: division by zero
2023-08-04 09:43:24,571 - ERROR - An error occurred while dividing by zero:
Traceback (most recent call last):
  File "/tmp/ipykernel_82372/3924246926.py", line 6, in <module>
    result = 10 / 0
             ~~~^~~
ZeroDivisionError: division by zero
